[2022-03-10 18:19:12,751] {taskinstance.py:1037} INFO - Dependencies all met for <TaskInstance: Demo.producer scheduled__2022-03-10T18:18:00+00:00 [queued]>
[2022-03-10 18:19:12,761] {taskinstance.py:1037} INFO - Dependencies all met for <TaskInstance: Demo.producer scheduled__2022-03-10T18:18:00+00:00 [queued]>
[2022-03-10 18:19:12,762] {taskinstance.py:1243} INFO - 
--------------------------------------------------------------------------------
[2022-03-10 18:19:12,762] {taskinstance.py:1244} INFO - Starting attempt 1 of 1
[2022-03-10 18:19:12,763] {taskinstance.py:1245} INFO - 
--------------------------------------------------------------------------------
[2022-03-10 18:19:12,774] {taskinstance.py:1264} INFO - Executing <Task(PythonOperator): producer> on 2022-03-10 18:18:00+00:00
[2022-03-10 18:19:12,778] {standard_task_runner.py:52} INFO - Started process 105 to run task
[2022-03-10 18:19:12,782] {standard_task_runner.py:76} INFO - Running: ['airflow', 'tasks', 'run', 'Demo', 'producer', 'scheduled__2022-03-10T18:18:00+00:00', '--job-id', '4', '--raw', '--subdir', 'DAGS_FOLDER/demo.py', '--cfg-path', '/tmp/tmpybnpx7dy', '--error-file', '/tmp/tmpznazrf3d']
[2022-03-10 18:19:12,783] {standard_task_runner.py:77} INFO - Job 4: Subtask producer
[2022-03-10 18:19:12,895] {logging_mixin.py:109} INFO - Running <TaskInstance: Demo.producer scheduled__2022-03-10T18:18:00+00:00 [running]> on host c17209ace312
[2022-03-10 18:19:13,037] {taskinstance.py:1431} INFO - Exporting the following env vars:
AIRFLOW_CTX_DAG_OWNER=airflow
AIRFLOW_CTX_DAG_ID=Demo
AIRFLOW_CTX_TASK_ID=producer
AIRFLOW_CTX_EXECUTION_DATE=2022-03-10T18:18:00+00:00
AIRFLOW_CTX_DAG_RUN_ID=scheduled__2022-03-10T18:18:00+00:00
[2022-03-10 18:19:13,040] {logging_mixin.py:109} INFO - Producing message @ 2022-03-10 18:19:13.040184 | Message = {'data_id': 40, 'name': 'BTC', 'timestamp': 1646936353}
[2022-03-10 18:19:13,041] {taskinstance.py:1718} ERROR - Task failed with exception
Traceback (most recent call last):
  File "/usr/local/lib/python3.7/site-packages/airflow/models/taskinstance.py", line 1334, in _run_raw_task
    self._execute_task_with_callbacks(context)
  File "/usr/local/lib/python3.7/site-packages/airflow/models/taskinstance.py", line 1460, in _execute_task_with_callbacks
    result = self._execute_task(context, self.task)
  File "/usr/local/lib/python3.7/site-packages/airflow/models/taskinstance.py", line 1516, in _execute_task
    result = execute_callable(context=context)
  File "/usr/local/lib/python3.7/site-packages/airflow/operators/python.py", line 174, in execute
    return_value = self.execute_callable()
  File "/usr/local/lib/python3.7/site-packages/airflow/operators/python.py", line 188, in execute_callable
    return self.python_callable(*self.op_args, **self.op_kwargs)
  File "/airflow/dags/demo.py", line 65, in demo_func
    producer.send('demo', item)
AttributeError: 'PythonOperator' object has no attribute 'send'
[2022-03-10 18:19:13,085] {taskinstance.py:1282} INFO - Marking task as FAILED. dag_id=Demo, task_id=producer, execution_date=20220310T181800, start_date=20220310T181912, end_date=20220310T181913
[2022-03-10 18:19:13,108] {standard_task_runner.py:92} ERROR - Failed to execute job 4 for task producer
Traceback (most recent call last):
  File "/usr/local/lib/python3.7/site-packages/airflow/task/task_runner/standard_task_runner.py", line 85, in _start_by_fork
    args.func(args, dag=self.dag)
  File "/usr/local/lib/python3.7/site-packages/airflow/cli/cli_parser.py", line 48, in command
    return func(*args, **kwargs)
  File "/usr/local/lib/python3.7/site-packages/airflow/utils/cli.py", line 92, in wrapper
    return f(*args, **kwargs)
  File "/usr/local/lib/python3.7/site-packages/airflow/cli/commands/task_command.py", line 298, in task_run
    _run_task_by_selected_method(args, dag, ti)
  File "/usr/local/lib/python3.7/site-packages/airflow/cli/commands/task_command.py", line 107, in _run_task_by_selected_method
    _run_raw_task(args, ti)
  File "/usr/local/lib/python3.7/site-packages/airflow/cli/commands/task_command.py", line 184, in _run_raw_task
    error_file=args.error_file,
  File "/usr/local/lib/python3.7/site-packages/airflow/utils/session.py", line 70, in wrapper
    return func(*args, session=session, **kwargs)
  File "/usr/local/lib/python3.7/site-packages/airflow/models/taskinstance.py", line 1334, in _run_raw_task
    self._execute_task_with_callbacks(context)
  File "/usr/local/lib/python3.7/site-packages/airflow/models/taskinstance.py", line 1460, in _execute_task_with_callbacks
    result = self._execute_task(context, self.task)
  File "/usr/local/lib/python3.7/site-packages/airflow/models/taskinstance.py", line 1516, in _execute_task
    result = execute_callable(context=context)
  File "/usr/local/lib/python3.7/site-packages/airflow/operators/python.py", line 174, in execute
    return_value = self.execute_callable()
  File "/usr/local/lib/python3.7/site-packages/airflow/operators/python.py", line 188, in execute_callable
    return self.python_callable(*self.op_args, **self.op_kwargs)
  File "/airflow/dags/demo.py", line 65, in demo_func
    producer.send('demo', item)
AttributeError: 'PythonOperator' object has no attribute 'send'
[2022-03-10 18:19:13,156] {local_task_job.py:154} INFO - Task exited with return code 1
[2022-03-10 18:19:13,243] {local_task_job.py:264} INFO - 0 downstream tasks scheduled from follow-on schedule check
